Workbook

Sheet JVC
A1: B1 JVC
A2: № | B2: Наименование товара | C2: ЦЕНА | D2: НОРМА | E2: ОСТАТОК ПРОШЛОГО ДНЯ | F2: ПРИХОД | G2: ПЕРЕМЕЩЕНИЕ | H2: ОСТАТОК ДОМА | I2: ПРОДАЖА | J2: СУММА | K2: ЗАЯВКА | L2: Доп к заявке | M2: ОСТАТОК ТЕКУЩЕГО ДНЯ
A3: 1 | B3: ABSOLUT BLUE LTR | C3: 100 | D3: 40 | E3: 7 | F3: 23 | H3: 24 | I3: =E3+F3-G3-H3 -> 6 | J3: =C3*I3 -> 600
A4: 2 | B4: J/W RED LABEL 1 LTR | C4: 100 | D4: 40 | E4: 17 | F4: 13 | H4: 28 | I4: =E4+F4-G4-H4 -> 2 | J4: =C4*I4 -> 200
A5: 3 | B5: J/W BLAK LABEL 1 LTR | C5: 200 | D5: 20 | E5: 8 | F5: 6 | H5: 13 | I5: =E5+F5-G5-H5 -> 1 | J5: =C5*I5 -> 200
A6: 4 | B6: JACK DANIELS LTR | C6: 200 | D6: 20 | E6: 6 | F6: 4 | H6: 10 | I6: =E6+F6-G6-H6 -> 0 | J6: =C6*I6 -> 0
A7: 5 | B7: CHIVAS REGAL 1 LTR | C7: 200 | D7: 20 | E7: 26 | F7: 10 | H7: 35 | I7: =E7+F7-G7-H7 -> 1 | J7: =C7*I7 -> 200
A8: 6 | B8: HEINEKEN BEER CANS 33CL | C8: 200 | D8: 15 | E8: 1 | F8: 6 | H8: 6 | I8: =E8+F8-G8-H8 -> 1 | J8: =C8*I8 -> 200
A9: 7 | B9: BUDWEISER BEER CAN 33/35 | C9: 200 | D9: 12 | E9: 4.5 | F9: 3.5 | H9: 7.5 | I9: =E9+F9-G9-H9 -> 0.5 | J9: =C9*I9 -> 100
A10: 8 | B10: CARLSBERG 50CL Can | C10: 200 | D10: 8 | E10: 2.5 | F10: 4.5 | H10: 4.5 | I10: =E10+F10-G10-H10 -> 2.5 | J10: =C10*I10 -> 500
A11: 9 | B11: RED HORSE 50CL Can | C11: 200 | D11: 5 | E11: 7.5 | H11: 7.5 | I11: =E11+F11-G11-H11 -> 0 | J11: =C11*I11 -> 0
A12: 10 | B12: AMSTEL LIGHT Slim Can 35 | C12: 200 | D12: 5 | E12: 1 | H12: 1 | I12: =E12+F12-G12-H12 -> 0 | J12: =C12*I12 -> 0
A13: 11 | B13: CORONA BEER BTL 35.5CL | C13: 300 | D13: 10 | E13: 2 | F13: 6 | H13: 7.5 | I13: =E13+F13-G13-H13 -> 0.5 | J13: =C13*I13 -> 150
A14: 12 | B14: STELLA 33CL BTLS | C14: 300 | D14: 2 | E14: 2 | H14: 2 | I14: =E14+F14-G14-H14 -> 0 | J14: =C14*I14 -> 0
A15: 13 | B15: STELLA ARTOIS 33 CL cans | C15: 200 | D15: 5 | E15: 0.5 | F15: 1.5 | H15: 2 | I15: =E15+F15-G15-H15 -> 0 | J15: =C15*I15 -> 0
A16: 14 | B16: HEINEKEN BEER BTL 33CL | C16: 300 | D16: 1.5 | E16: 1 | F16: 1 | H16: 2 | I16: =E16+F16-G16-H16 -> 0 | J16: =C16*I16 -> 0
A17: 15 | B17: BUDWEISER BERR BTL 33cl | C17: 300 | D17: 1.5 | E17: 2 | H17: 2 | I17: =E17+F17-G17-H17 -> 0 | J17: =C17*I17 -> 0
A18: 16 | B18: SMIRNOFF ICE RED 27,5CL | C18: 300 | D18: 1.5 | E18: 1.5 | F18: 0.5 | H18: 1 | I18: =E18+F18-G18-H18 -> 1 | J18: =C18*I18 -> 300
A19: 17 | B19: PERONI NASTRO AZURO BEER | C19: 300 | D19: 1 | E19: 0.5 | F19: 1.5 | H19: 2 | I19: =E19+F19-G19-H19 -> 0 | J19: =C19*I19 -> 0
A20: 18 | B20: JC CHARDONNAY 75CL | C20: 100 | D20: 20 | E20: 0 | H20: 0 | I20: =E20+F20-G20-H20 -> 0 | J20: =C20*I20 -> 0
A21: 19 | B21: JC SHIRAZ CABARNET 75CL | C21: 100 | D21: 20 | E21: 15 | H21: 14 | I21: =E21+F21-G21-H21 -> 1 | J21: =C21*I21 -> 100
A22: 20 | B22: CES PINOT GRIG D VEN FIO | C22: 100 | D22: 20 | E22: 7 | F22: 13 | H22: 20 | I22: =E22+F22-G22-H22 -> 0 | J22: =C22*I22 -> 0
A23: 21 | B23: Le GRAND Noir SAUV BLANC | C23: 100 | D23: 20 | E23: 6 | F23: 14 | H23: 17 | I23: =E23+F23-G23-H23 -> 3 | J23: =C23*I23 -> 300
A24: 22 | B24: Le GRAND Noir MERLOT 75C | C24: 100 | D24: 15 | E24: 11 | F24: 9 | H24: 20 | I24: =E24+F24-G24-H24 -> 0 | J24: =C24*I24 -> 0
A25: 23 | B25: MIP Collection ROSE Provienc 7 | C25: 150 | D25: 3 | E25: 1 | H25: 1 | I25: =E25+F25-G25-H25 -> 0 | J25: =C25*I25 -> 0
A26: 24 | B26: CH KSARA SUNSET ROSE 75C | C26: 100 | D26: 15 | E26: 5 | H26: 5 | I26: =E26+F26-G26-H26 -> 0 | J26: =C26*I26 -> 0
A27: 25 | B27: MATEUS ROSE 75CL | C27: 100 | D27: 15 | E27: 1 | F27: 6 | H27: 7 | I27: =E27+F27-G27-H27 -> 0 | J27: =C27*I27 -> 0
A28: 26 | B28: BACARDI WHITE RUM LTR | C28: 100 | D28: 15 | E28: 2 | F28: 4 | H28: 6 | I28: =E28+F28-G28-H28 -> 0 | J28: =C28*I28 -> 0
A29: 27 | B29: BACARDI BLACK. 1 LTR | C29: 100 | D29: 6 | E29: 6 | H29: 6 | I29: =E29+F29-G29-H29 -> 0 | J29: =C29*I29 -> 0
A30: 28 | B30: BACARDI GOLD LTR | C30: 100 | D30: 8 | E30: 4 | F30: 2 | H30: 6 | I30: =E30+F30-G30-H30 -> 0 | J30: =C30*I30 -> 0
A31: 29 | B31: JOSE CUERVO GOLD LTR | C31: 100 | D31: 10 | E31: 6 | F31: 4 | H31: 8 | I31: =E31+F31-G31-H31 -> 2 | J31: =C31*I31 -> 200
A32: 30 | B32: JOSE CUERVO SILVER Espec | C32: 100 | D32: 10 | E32: 3 | F32: 7 | H32: 10 | I32: =E32+F32-G32-H32 -> 0 | J32: =C32*I32 -> 0
A33: 31 | B33: TANQUERAY GIN LTR | C33: 200 | D33: 2 | E33: 3 | H33: 3 | I33: =E33+F33-G33-H33 -> 0 | J33: =C33*I33 -> 0
A34: 32 | B34: GORDONS PINK GIN Ltr | C34: 150 | D34: 6 | E34: 3 | H34: 3 | I34: =E34+F34-G34-H34 -> 0 | J34: =C34*I34 -> 0
A35: 33 | B35: GORDONS GIN LTR | C35: 100 | D35: 12 | E35: 0 | F35: 10 | H35: 9 | I35: =E35+F35-G35-H35 -> 1 | J35: =C35*I35 -> 100
A36: 34 | B36: BOMBAY SAPPHIRE GIN LTR | C36: 150 | D36: 12 | E36: 2 | F36: 8 | H36: 8 | I36: =E36+F36-G36-H36 -> 2 | J36: =C36*I36 -> 300
A37: 35 | B37: HENDRICKS GIN 1 LTR | C37: 250 | D37: 10 | E37: 7 | H37: 7 | I37: =E37+F37-G37-H37 -> 0 | J37: =C37*I37 -> 0
A38: 36 | B38: CAPTAIN MORGAN BLK LTR | C38: 150 | D38: 3 | E38: 7 | H38: 7 | I38: =E38+F38-G38-H38 -> 0 | J38: =C38*I38 -> 0
A39: 37 | B39: CAPTAIN MORGAN SPICED GO | C39: 150 | D39: 3 | E39: 4 | F39: 3 | H39: 7 | I39: =E39+F39-G39-H39 -> 0 | J39: =C39*I39 -> 0
A40: 38 | B40: MALIBU WHITHE RUM LTR | C40: 150 | D40: 5 | E40: 2 | H40: 2 | I40: =E40+F40-G40-H40 -> 0 | J40: =C40*I40 -> 0
...

Sheet Bussines Bay
A1: B2 Bussines Bay
A2: № | B2: Наименование товара | C2: ЦЕНА | D2: НОРМА | E2: ОСТАТОК ПРОШЛОГО ДНЯ | F2: ПРИХОД | G2: ПЕРЕМЕЩЕНИЕ | H2: ОСТАТОК ДОМА | I2: ПРОДАЖА | J2: СУММА | K2: ЗАЯВКА | L2: Доп к заявке | M2: ОСТАТОК ТЕКУЩЕГО ДНЯ
A3: 1 | B3: ABSOLUT BLUE LTR | C3: 100 | D3: 40 | E3: 20 | F3: 30 | H3: 47 | I3: =E3+F3-G3-H3 -> 3 | J3: =C3*I3 -> 300
A4: 2 | B4: J/W RED LABEL 1 LTR | C4: 100 | D4: 40 | E4: 28 | F4: 24 | H4: 48 | I4: =E4+F4-G4-H4 -> 4 | J4: =C4*I4 -> 400
A5: 3 | B5: J/W BLAK LABEL 1 LTR | C5: 200 | D5: 20 | E5: 15 | F5: 5 | H5: 19 | I5: =E5+F5-G5-H5 -> 1 | J5: =C5*I5 -> 200
A6: 4 | B6: JACK DANIELS LTR | C6: 200 | D6: 20 | E6: 19 | F6: 1 | H6: 19 | I6: =E6+F6-G6-H6 -> 1 | J6: =C6*I6 -> 200
A7: 5 | B7: CHIVAS REGAL 1 LTR | C7: 200 | D7: 20 | E7: 17 | F7: 3 | H7: 19 | I7: =E7+F7-G7-H7 -> 1 | J7: =C7*I7 -> 200
A8: 6 | B8: HEINEKEN BEER CANS 33CL | C8: 200 | D8: 15 | E8: 5 | F8: 7 | H8: 11 | I8: =E8+F8-G8-H8 -> 1 | J8: =C8*I8 -> 200
A9: 7 | B9: BUDWEISER BEER CAN 33/35 | C9: 200 | D9: 12 | E9: 7 | F9: 6 | H9: 12.5 | I9: =E9+F9-G9-H9 -> 0.5 | J9: =C9*I9 -> 100
A10: 8 | B10: CARLSBERG 50CL Can | C10: 200 | D10: 8 | E10: 3.5 | F10: 8 | H10: 11.5 | I10: =E10+F10-G10-H10 -> 0 | J10: =C10*I10 -> 0
A11: 9 | B11: RED HORSE 50CL Can | C11: 200 | D11: 5 | E11: 2 | F11: 1 | H11: 2.5 | I11: =E11+F11-G11-H11 -> 0.5 | J11: =C11*I11 -> 100
A12: 10 | B12: AMSTEL LIGHT Slim Can 35 | C12: 200 | D12: 5 | E12: 3 | H12: 3 | I12: =E12+F12-G12-H12 -> 0 | J12: =C12*I12 -> 0
A13: 11 | B13: CORONA BEER BTL 35.5CL | C13: 300 | D13: 10 | E13: 1.5 | F13: 12 | H13: 11.5 | I13: =E13+F13-G13-H13 -> 2 | J13: =C13*I13 -> 600
A14: 12 | B14: STELLA 33CL BTLS | C14: 300 | D14: 2 | E14: 2.5 | F14: 0.5 | H14: 3 | I14: =E14+F14-G14-H14 -> 0 | J14: =C14*I14 -> 0
A15: 13 | B15: STELLA ARTOIS 33 CL cans | C15: 200 | D15: 5 | E15: 2 | H15: 2 | I15: =E15+F15-G15-H15 -> 0 | J15: =C15*I15 -> 0
A16: 14 | B16: HEINEKEN BEER BTL 33CL | C16: 300 | D16: 1.5 | E16: 2 | F16: 1 | H16: 3 | I16: =E16+F16-G16-H16 -> 0 | J16: =C16*I16 -> 0
A17: 15 | B17: BUDWEISER BERR BTL 33cl | C17: 300 | D17: 1.5 | E17: 3 | H17: 3 | I17: =E17+F17-G17-H17 -> 0 | J17: =C17*I17 -> 0
A18: 16 | B18: SMIRNOFF ICE RED 27,5CL | C18: 300 | D18: 1.5 | E18: 1.5 | F18: 1.5 | H18: 2.5 | I18: =E18+F18-G18-H18 -> 0.5 | J18: =C18*I18 -> 150
A19: 17 | B19: PERONI NASTRO AZURO BEER | C19: 300 | D19: 1 | E19: 2.5 | F19: 0.5 | H19: 3 | I19: =E19+F19-G19-H19 -> 0 | J19: =C19*I19 -> 0
A20: 18 | B20: JC CHARDONNAY 75CL | C20: 100 | D20: 20 | E20: 0 | H20: 0 | I20: =E20+F20-G20-H20 -> 0 | J20: =C20*I20 -> 0
A21: 19 | B21: JC SHIRAZ CABARNET 75CL | C21: 100 | D21: 20 | E21: 16 | F21: 6 | H21: 22 | I21: =E21+F21-G21-H21 -> 0 | J21: =C21*I21 -> 0
A22: 20 | B22: CES PINOT GRIG D VEN FIO | C22: 100 | D22: 20 | E22: 14 | F22: 6 | H22: 19 | I22: =E22+F22-G22-H22 -> 1 | J22: =C22*I22 -> 100
A23: 21 | B23: Le GRAND Noir SAUV BLANC | C23: 100 | D23: 20 | E23: 5 | F23: 18 | H23: 22 | I23: =E23+F23-G23-H23 -> 1 | J23: =C23*I23 -> 100
A24: 22 | B24: Le GRAND Noir MERLOT 75C | C24: 100 | D24: 15 | E24: 12 | F24: 3 | H24: 15 | I24: =E24+F24-G24-H24 -> 0 | J24: =C24*I24 -> 0
A25: 23 | B25: MIP Collection ROSE Provienc 7 | C25: 150 | D25: 3 | E25: 4 | H25: 4 | I25: =E25+F25-G25-H25 -> 0 | J25: =C25*I25 -> 0
A26: 24 | B26: CH KSARA SUNSET ROSE 75C | C26: 100 | D26: 15 | E26: 12 | H26: 12 | I26: =E26+F26-G26-H26 -> 0 | J26: =C26*I26 -> 0
A27: 25 | B27: MATEUS ROSE 75CL | C27: 100 | D27: 15 | E27: 11 | F27: 2 | H27: 13 | I27: =E27+F27-G27-H27 -> 0 | J27: =C27*I27 -> 0
A28: 26 | B28: BACARDI WHITE RUM LTR | C28: 100 | D28: 15 | E28: 9 | F28: 1 | H28: 10 | I28: =E28+F28-G28-H28 -> 0 | J28: =C28*I28 -> 0
A29: 27 | B29: BACARDI BLACK. 1 LTR | C29: 100 | D29: 6 | E29: 9 | F29: 1 | H29: 9 | I29: =E29+F29-G29-H29 -> 1 | J29: =C29*I29 -> 100
A30: 28 | B30: BACARDI GOLD LTR | C30: 100 | D30: 8 | E30: 7 | F30: 3 | H30: 10 | I30: =E30+F30-G30-H30 -> 0 | J30: =C30*I30 -> 0
A31: 29 | B31: JOSE CUERVO GOLD LTR | C31: 100 | D31: 10 | E31: 10 | H31: 7 | I31: =E31+F31-G31-H31 -> 3 | J31: =C31*I31 -> 300
A32: 30 | B32: JOSE CUERVO SILVER Espec | C32: 100 | D32: 10 | E32: 9 | F32: 1 | H32: 10 | I32: =E32+F32-G32-H32 -> 0 | J32: =C32*I32 -> 0
A33: 31 | B33: TANQUERAY GIN LTR | C33: 200 | D33: 2 | E33: 2 | H33: 2 | I33: =E33+F33-G33-H33 -> 0 | J33: =C33*I33 -> 0
A34: 32 | B34: GORDONS PINK GIN Ltr | C34: 150 | D34: 6 | E34: 4 | H34: 4 | I34: =E34+F34-G34-H34 -> 0 | J34: =C34*I34 -> 0
A35: 33 | B35: GORDONS GIN LTR | C35: 100 | D35: 12 | E35: 10 | H35: 10 | I35: =E35+F35-G35-H35 -> 0 | J35: =C35*I35 -> 0
A36: 34 | B36: BOMBAY SAPPHIRE GIN LTR | C36: 150 | D36: 12 | E36: 7 | F36: 3 | H36: 9 | I36: =E36+F36-G36-H36 -> 1 | J36: =C36*I36 -> 150
A37: 35 | B37: HENDRICKS GIN 1 LTR | C37: 250 | D37: 10 | E37: 9 | F37: 2 | H37: 10 | I37: =E37+F37-G37-H37 -> 1 | J37: =C37*I37 -> 250
A38: 36 | B38: CAPTAIN MORGAN BLK LTR | C38: 150 | D38: 3 | E38: 6 | H38: 6 | I38: =E38+F38-G38-H38 -> 0 | J38: =C38*I38 -> 0
A39: 37 | B39: CAPTAIN MORGAN SPICED GO | C39: 150 | D39: 3 | E39: 5 | H39: 5 | I39: =E39+F39-G39-H39 -> 0 | J39: =C39*I39 -> 0
A40: 38 | B40: MALIBU WHITHE RUM LTR | C40: 150 | D40: 5 | E40: 5 | H40: 5 | I40: =E40+F40-G40-H40 -> 0 | J40: =C40*I40 -> 0
...

Sheet Selicon
A1: B3 Silicon Oasis
A2: № | B2: Наименование товара | C2: ЦЕНА | D2: НОРМА | E2: ОСТАТОК ПРОШЛОГО ДНЯ | F2: ПРИХОД | G2: ПЕРЕМЕЩЕНИЕ | H2: ОСТАТОК ДОМА | I2: ПРОДАЖА | J2: СУММА | K2: ЗАЯВКА | L2: Доп к заявке | M2: ОСТАТОК ТЕКУЩЕГО ДНЯ
A3: 1 | B3: ABSOLUT BLUE LTR | C3: 100 | D3: 40 | E3: 38 | H3: 37 | I3: =E3+F3-G3-H3 -> 1 | J3: =C3*I3 -> 100
A4: 2 | B4: J/W RED LABEL 1 LTR | C4: 100 | D4: 40 | E4: 33 | H4: 31 | I4: =E4+F4-G4-H4 -> 2 | J4: =C4*I4 -> 200
A5: 3 | B5: J/W BLAK LABEL 1 LTR | C5: 200 | D5: 20 | E5: 12 | H5: 12 | I5: =E5+F5-G5-H5 -> 0 | J5: =C5*I5 -> 0
A6: 4 | B6: JACK DANIELS LTR | C6: 200 | D6: 20 | E6: 15 | H6: 15 | I6: =E6+F6-G6-H6 -> 0 | J6: =C6*I6 -> 0
A7: 5 | B7: CHIVAS REGAL 1 LTR | C7: 200 | D7: 20 | E7: 11 | H7: 10 | I7: =E7+F7-G7-H7 -> 1 | J7: =C7*I7 -> 200
A8: 6 | B8: HEINEKEN BEER CANS 33CL | C8: 200 | D8: 15 | E8: 16.5 | H8: 16.5 | I8: =E8+F8-G8-H8 -> 0 | J8: =C8*I8 -> 0
A9: 7 | B9: BUDWEISER BEER CAN 33/35 | C9: 200 | D9: 12 | E9: 8.5 | H9: 7 | I9: =E9+F9-G9-H9 -> 1.5 | J9: =C9*I9 -> 300
A10: 8 | B10: CARLSBERG 50CL Can | C10: 200 | D10: 8 | E10: 7.5 | H10: 5.5 | I10: =E10+F10-G10-H10 -> 2 | J10: =C10*I10 -> 400
A11: 9 | B11: RED HORSE 50CL Can | C11: 200 | D11: 5 | E11: 5.5 | H11: 5 | I11: =E11+F11-G11-H11 -> 0.5 | J11: =C11*I11 -> 100
A12: 10 | B12: AMSTEL LIGHT Slim Can 35 | C12: 200 | D12: 5 | E12: 3.5 | H12: 3.5 | I12: =E12+F12-G12-H12 -> 0 | J12: =C12*I12 -> 0
A13: 11 | B13: CORONA BEER BTL 35.5CL | C13: 300 | D13: 10 | E13: 5 | H13: 4 | I13: =E13+F13-G13-H13 -> 1 | J13: =C13*I13 -> 300
A14: 12 | B14: STELLA 33CL BTLS | C14: 300 | D14: 2 | E14: 2 | H14: 2 | I14: =E14+F14-G14-H14 -> 0 | J14: =C14*I14 -> 0
... A124: 122 | B124: OYSTER BAY SAUVIGNON | C124: 150 | D124: 6 | E124: 4 | H124: 4 | I124: =E124+F124-G124-H124 -> 0 | J124: =C124*I124 -> 0
J125: =SUM(J3:J124) -> 3000
C128: Имя водителя | F128: Азиз | G128: Фариддун | L128: Сверка с итогами продаж день (должно быть 0,00)
C129: ВЫРУЧКА | F129: 2300 | G129: 1200 | L129: =(E129+F129+G129+H129+I129+J129+K129)-J125 -> 500
C130: Расходы на питание | F130: 80 | G130: 80
C131: Мы вернули долг
C132: Мы должны | E132: alawin | F132: 500
C133: Клиент вернул долг
C134: Клиент взял в долг
C135: Скидки
C136: бензин | F136: 175 | G136: 100
C137: праздник
C138: для дома
C139: мойка
C140: тонировка
D141: охрана
C143: СДАЛ | F143: 2045 | G143: 1020
C144: ДОЛЖЕН СДАТЬ | F144: =F129-F130-F131+F133-F134-F135-F136-F137-F138-F139-F140-F141-F142 -> 2045 | G144: =G129-G130-G131+G133-G134-G135-G136-G137-G138-G139-G140-G141-G142 -> 1020 | H144: =H129-H130-H131+H132+H133-H134-H135-H136-H137-H138-H139-H140-H141-H142 -> 0 | I144: =I129-I130-I131+I132+I133-I134-I135-I136-I137-I138-I139-I140-I141-I142 -> 0 | J144: =J129-J130-J131+J132+J133-J134-J135-J136-J137-J138-J139-J140-J141-J142 -> 0 | K144: =K129-K130-K131+K132+K133-K134-K135-K136-K137-K138-K139-K140-K141-K142 -> 0
C145: Плюс +/- Недостача | F145: =F143-F144 -> 0 | G145: =G143-G144 -> 0 | H145: =H143-H144 -> 0 | I145: =I143-I144 -> 0 | J145: =J143-J144 -> 0 | K145: =K143-K144 -> 0
H146: ИТОГО ОБЩАЯ Плюс +/- Недостача | K146: =E145+F145+G145+H145+I145+J145+K145 -> 0
E148: ИТОГО СУММА ПРОДАЖ | G148: =J125 -> 3000
E149: ИТОГО СДАЛИ СУММА ДЕНЬ | G149: =E143+F143+G143+H143+I143+J143+K143 -> 3065

Sheet Al-Qusais
A1: B4 Al Qusais
A2: № | B2: Наименование товара | C2: ЦЕНА | D2: НОРМА | E2: ОСТАТОК ПРОШЛОГО ДНЯ | F2: ПРИХОД | G2: ПЕРЕМЕЩЕНИЕ | H2: ОСТАТОК ДОМА | I2: ПРОДАЖА | J2: СУММА | K2: ЗАЯВКА | L2: Доп к заявке | M2: ОСТАТОК ТЕКУЩЕГО ДНЯ
A3: 1 | B3: ABSOLUT BLUE LTR | C3: 100 | D3: 40 | E3: 26 | F3: 18 | H3: 37 | I3: =E3+F3-G3-H3 -> 7 | J3: =C3*I3 -> 700
A4: 2 | B4: J/W RED LABEL 1 LTR | C4: 100 | D4: 40 | E4: 18 | F4: 27 | H4: 43 | I4: =E4+F4-G4-H4 -> 2 | J4: =C4*I4 -> 200
A5: 3 | B5: J/W BLAK LABEL 1 LTR | C5: 200 | D5: 20 | E5: 12 | F5: 6 | H5: 16 | I5: =E5+F5-G5-H5 -> 2 | J5: =C5*I5 -> 400
A6: 4 | B6: JACK DANIELS LTR | C6: 200 | D6: 20 | E6: 12 | F6: 3 | H6: 15 | I6: =E6+F6-G6-H6 -> 0 | J6: =C6*I6 -> 0
A7: 5 | B7: CHIVAS REGAL 1 LTR | C7: 200 | D7: 20 | E7: 9 | F7: 5 | H7: 12 | I7: =E7+F7-G7-H7 -> 2 | J7: =C7*I7 -> 400
A8: 6 | B8: HEINEKEN BEER CANS 33CL | C8: 200 | D8: 15 | E8: 7.5 | F8: 5.5 | H8: 11 | I8: =E8+F8-G8-H8 -> 2 | J8: =C8*I8 -> 400
A9: 7 | B9: BUDWEISER BEER CAN 33/35 | C9: 200 | D9: 12 | E9: 11.5 | F9: 2.5 | H9: 14 | I9: =E9+F9-G9-H9 -> 0 | J9: =C9*I9 -> 0
A10: 8 | B10: CARLSBERG 50CL Can | C10: 200 | D10: 8 | E10: 11 | F10: 3 | H10: 13.5 | I10: =E10+F10-G10-H10 -> 0.5 | J10: =C10*I10 -> 100
A11: 9 | B11: RED HORSE 50CL Can | C11: 200 | D11: 5 | E11: 3.5 | F11: 1 | H11: 4.5 | I11: =E11+F11-G11-H11 -> 0 | J11: =C11*I11 -> 0
A12: 10 | B12: AMSTEL LIGHT Slim Can 35 | C12: 200 | D12: 5 | E12: 1.5 | F12: 0.5 | H12: 2 | I12: =E12+F12-G12-H12 -> 0 | J12: =C12*I12 -> 0
A13: 11 | B13: CORONA BEER BTL 35.5CL | C13: 300 | D13: 10 | E13: 4.5 | F13: 2.5 | H13: 6.5 | I13: =E13+F13-G13-H13 -> 0.5 | J13: =C13*I13 -> 150
A14: 12 | B14: STELLA 33CL BTLS | C14: 300 | D14: 2 | E14: 1 | H14: 1 | I14: =E14+F14-G14-H14 -> 0 | J14: =C14*I14 -> 0
A15: 13 | B15: STELLA ARTOIS 33 CL cans | C15: 200 | D15: 5 | E15: 2 | H15: 2 | I15: =E15+F15-G15-H15 -> 0 | J15: =C15*I15 -> 0
A16: 14 | B16: HEINEKEN BEER BTL 33CL | C16: 300 | D16: 1.5 | E16: 0.5 | F16: 0.5 | H16: 1 | I16: =E16+F16-G16-H16 -> 0 | J16: =C16*I16 -> 0
A17: 15 | B17: BUDWEISER BERR BTL 33cl | C17: 300 | D17: 1.5 | E17: 1 | H17: 1 | I17: =E17+F17-G17-H17 -> 0 | J17: =C17*I17 -> 0
A18: 16 | B18: SMIRNOFF ICE RED 27,5CL | C18: 300 | D18: 1.5 | E18: 1 | H18: 1 | I18: =E18+F18-G18-H18 -> 0 | J18: =C18*I18 -> 0
A19: 17 | B19: PERONI NASTRO AZURO BEER | C19: 300 | D19: 1 | E19: 1 | H19: 1 | I19: =E19+F19-G19-H19 -> 0 | J19: =C19*I19 -> 0
A20: 18 | B20: JC CHARDONNAY 75CL | C20: 100 | D20: 20 | E20: 2 | H20: 2 | I20: =E20+F20-G20-H20 -> 0 | J20: =C20*I20 -> 0
A21: 19 | B21: JC SHIRAZ CABARNET 75CL | C21: 100 | D21: 20 | E21: 9 | F21: 1 | H21: 10 | I21: =E21+F21-G21-H21 -> 0 | J21: =C21*I21 -> 0
A22: 20 | B22: CES PINOT GRIG D VEN FIO | C22: 100 | D22: 20 | E22: 6 | H22: 6 | I22: =E22+F22-G22-H22 -> 0 | J22: =C22*I22 -> 0
A23: 21 | B23: Le GRAND Noir SAUV BLANC | C23: 100 | D23: 20 | E23: 9 | H23: 8 | I23: =E23+F23-G23-H23 -> 1 | J23: =C23*I23 -> 100
A24: 22 | B24: Le GRAND Noir MERLOT 75C | C24: 100 | D24: 15 | E24: 10 | H24: 10 | I24: =E24+F24-G24-H24 -> 0 | J24: =C24*I24 -> 0
A25: 23 | B25: MIP Collection ROSE Provienc 7 | C25: 150 | D25: 3 | E25: 0 | H25: 0 | I25: =E25+F25-G25-H25 -> 0 | J25: =C25*I25 -> 0
A26: 24 | B26: CH KSARA SUNSET ROSE 75C | C26: 100 | D26: 15 | E26: 6 | H26: 6 | I26: =E26+F26-G26-H26 -> 0 | J26: =C26*I26 -> 0
A27: 25 | B27: MATEUS ROSE 75CL | C27: 100 | D27: 15 | E27: 9 | H27: 9 | I27: =E27+F27-G27-H27 -> 0 | J27: =C27*I27 -> 0
A28: 26 | B28: BACARDI WHITE RUM LTR | C28: 100 | D28: 15 | E28: 10 | H28: 10 | I28: =E28+F28-G28-H28 -> 0 | J28: =C28*I28 -> 0
A29: 27 | B29: BACARDI BLACK. 1 LTR | C29: 100 | D29: 6 | E29: 10 | H29: 10 | I29: =E29+F29-G29-H29 -> 0 | J29: =C29*I29 -> 0
A30: 28 | B30: BACARDI GOLD LTR | C30: 100 | D30: 8 | E30: 10 | H30: 10 | I30: =E30+F30-G30-H30 -> 0 | J30: =C30*I30 -> 0
A31: 29 | B31: JOSE CUERVO GOLD LTR | C31: 100 | D31: 10 | E31: 7 | F31: 1 | H31: 8 | I31: =E31+F31-G31-H31 -> 0 | J31: =C31*I31 -> 0
A32: 30 | B32: JOSE CUERVO SILVER Espec | C32: 100 | D32: 10 | E32: 9 | F32: 1 | H32: 10 | I32: =E32+F32-G32-H32 -> 0 | J32: =C32*I32 -> 0
A33: 31 | B33: TANQUERAY GIN LTR | C33: 200 | D33: 2 | E33: 0 | H33: 0 | I33: =E33+F33-G33-H33 -> 0 | J33: =C33*I33 -> 0
A34: 32 | B34: GORDONS PINK GIN Ltr | C34: 150 | D34: 6 | E34: 2 | H34: 2 | I34: =E34+F34-G34-H34 -> 0 | J34: =C34*I34 -> 0
A35: 33 | B35: GORDONS GIN LTR | C35: 100 | D35: 12 | E35: 10 | H35: 10 | I35: =E35+F35-G35-H35 -> 0 | J35: =C35*I35 -> 0
A36: 34 | B36: BOMBAY SAPPHIRE GIN LTR | C36: 150 | D36: 12 | E36: 6 | F36: 2 | H36: 8 | I36: =E36+F36-G36-H36 -> 0 | J36: =C36*I36 -> 0
A37: 35 | B37: HENDRICKS GIN 1 LTR | C37: 250 | D37: 10 | E37: 5 | H37: 5 | I37: =E37+F37-G37-H37 -> 0 | J37: =C37*I37 -> 0
A38: 36 | B38: CAPTAIN MORGAN BLK LTR | C38: 150 | D38: 3 | E38: 3 | H38: 3 | I38: =E38+F38-G38-H38 -> 0 | J38: =C38*I38 -> 0
A39: 37 | B39: CAPTAIN MORGAN SPICED GO | C39: 150 | D39: 3 | E39: 3 | H39: 3 | I39: =E39+F39-G39-H39 -> 0 | J39: =C39*I39 -> 0
A40: 38 | B40: MALIBU WHITHE RUM LTR | C40: 150 | D40: 5 | E40: 3 | H40: 3 | I40: =E40+F40-G40-H40 -> 0 | J40: =C40*I40 -> 0
...

Sheet Tikom
A1: B5 Tikkom
A2: № | B2: Наименование товара | C2: ЦЕНА | D2: НОРМА | E2: ОСТАТОК ПРОШЛОГО ДНЯ | F2: ПРИХОД | G2: ПЕРЕМЕЩЕНИЕ | H2: ОСТАТОК ДОМА | I2: ПРОДАЖА | J2: СУММА | K2: ЗАЯВКА | L2: Доп к заявке | M2: ОСТАТОК ТЕКУЩЕГО ДНЯ
A3: 1 | B3: ABSOLUT BLUE LTR | C3: 100 | D3: 40 | E3: 4 | F3: 26 | H3: 24 | I3: =E3+F3-G3-H3 -> 6 | J3: =C3*I3 -> 600
A4: 2 | B4: J/W RED LABEL 1 LTR | C4: 100 | D4: 40 | E4: 9 | F4: 24 | H4: 30 | I4: =E4+F4-G4-H4 -> 3 | J4: =C4*I4 -> 300
A5: 3 | B5: J/W BLAK LABEL 1 LTR | C5: 200 | D5: 20 | E5: 1 | F5: 9 | H5: 7 | I5: =E5+F5-G5-H5 -> 3 | J5: =C5*I5 -> 600
A6: 4 | B6: JACK DANIELS LTR | C6: 200 | D6: 20 | E6: 7 | H6: 6 | I6: =E6+F6-G6-H6 -> 1 | J6: =C6*I6 -> 200
A7: 5 | B7: CHIVAS REGAL 1 LTR | C7: 200 | D7: 20 | E7: 6 | H7: 6 | I7: =E7+F7-G7-H7 -> 0 | J7: =C7*I7 -> 0
A8: 6 | B8: HEINEKEN BEER CANS 33CL | C8: 200 | D8: 15 | E8: 1 | F8: 5 | H8: 4 | I8: =E8+F8-G8-H8 -> 2 | J8: =C8*I8 -> 400
A9: 7 | B9: BUDWEISER BEER CAN 33/35 | C9: 200 | D9: 12 | E9: 3.5 | F9: 1.5 | H9: 4 | I9: =E9+F9-G9-H9 -> 1 | J9: =C9*I9 -> 200
A10: 8 | B10: CARLSBERG 50CL Can | C10: 200 | D10: 8 | E10: 2.5 | F10: 3.5 | H10: 6 | I10: =E10+F10-G10-H10 -> 0 | J10: =C10*I10 -> 0
A11: 9 | B11: RED HORSE 50CL Can | C11: 200 | D11: 5 | E11: 0 | H11: 0 | I11: =E11+F11-G11-H11 -> 0 | J11: =C11*I11 -> 0
A12: 10 | B12: AMSTEL LIGHT Slim Can 35 | C12: 200 | D12: 5 | E12: 0 | H12: 0 | I12: =E12+F12-G12-H12 -> 0 | J12: =C12*I12 -> 0
A13: 11 | B13: CORONA BEER BTL 35.5CL | C13: 300 | D13: 10 | E13: 0 | F13: 7 | H13: 7 | I13: =E13+F13-G13-H13 -> 0 | J13: =C13*I13 -> 0
A14: 12 | B14: STELLA 33CL BTLS | C14: 300 | D14: 2 | E14: 0.5 | H14: 0.5 | I14: =E14+F14-G14-H14 -> 0 | J14: =C14*I14 -> 0
A15: 13 | B15: STELLA ARTOIS 33 CL cans | C15: 200 | D15: 5 | E15: 0 | H15: 0 | I15: =E15+F15-G15-H15 -> 0 | J15: =C15*I15 -> 0
A16: 14 | B16: HEINEKEN BEER BTL 33CL | C16: 300 | D16: 1.5 | E16: 0.5 | H16: 0.5 | I16: =E16+F16-G16-H16 -> 0 | J16: =C16*I16 -> 0
A17: 15 | B17: BUDWEISER BERR BTL 33cl | C17: 300 | D17: 1.5 | E17: 0.5 | H17: 0.5 | I17: =E17+F17-G17-H17 -> 0 | J17: =C17*I17 -> 0
A18: 16 | B18: SMIRNOFF ICE RED 27,5CL | C18: 300 | D18: 1.5 | E18: 0 | F18: 0.5 | H18: 0.5 | I18: =E18+F18-G18-H18 -> 0 | J18: =C18*I18 -> 0
A19: 17 | B19: PERONI NASTRO AZURO BEER | C19: 300 | D19: 1 | E19: 0.5 | H19: 0.5 | I19: =E19+F19-G19-H19 -> 0 | J19: =C19*I19 -> 0
A20: 18 | B20: JC CHARDONNAY 75CL | C20: 100 | D20: 20 | E20: 0 | H20: 0 | I20: =E20+F20-G20-H20 -> 0 | J20: =C20*I20 -> 0
A21: 19 | B21: JC SHIRAZ CABARNET 75CL | C21: 100 | D21: 20 | E21: 13 | H21: 13 | I21: =E21+F21-G21-H21 -> 0 | J21: =C21*I21 -> 0
A22: 20 | B22: CES PINOT GRIG D VEN FIO | C22: 100 | D22: 20 | E22: 5 | F22: 5 | H22: 10 | I22: =E22+F22-G22-H22 -> 0 | J22: =C22*I22 -> 0
A23: 21 | B23: Le GRAND Noir SAUV BLANC | C23: 100 | D23: 20 | E23: 2 | F23: 13 | H23: 14 | I23: =E23+F23-G23-H23 -> 1 | J23: =C23*I23 -> 100
A24: 22 | B24: Le GRAND Noir MERLOT 75C | C24: 100 | D24: 15 | E24: 4 | F24: 6 | H24: 10 | I24: =E24+F24-G24-H24 -> 0 | J24: =C24*I24 -> 0
A25: 23 | B25: MIP Collection ROSE Provienc 7 | C25: 150 | D25: 3 | E25: 2 | H25: 2 | I25: =E25+F25-G25-H25 -> 0 | J25: =C25*I25 -> 0
A26: 24 | B26: CH KSARA SUNSET ROSE 75C | C26: 100 | D26: 15 | E26: 6 | H26: 5 | I26: =E26+F26-G26-H26 -> 1 | J26: =C26*I26 -> 100
A27: 25 | B27: MATEUS ROSE 75CL | C27: 100 | D27: 15 | E27: 3 | F27: 2 | H27: 5 | I27: =E27+F27-G27-H27 -> 0 | J27: =C27*I27 -> 0
A28: 26 | B28: BACARDI WHITE RUM LTR | C28: 100 | D28: 15 | E28: 4 | H28: 4 | I28: =E28+F28-G28-H28 -> 0 | J28: =C28*I28 -> 0
A29: 27 | B29: BACARDI BLACK. 1 LTR | C29: 100 | D29: 6 | E29: 3 | H29: 3 | I29: =E29+F29-G29-H29 -> 0 | J29: =C29*I29 -> 0
A30: 28 | B30: BACARDI GOLD LTR | C30: 100 | D30: 8 | E30: 5 | H30: 4 | I30: =E30+F30-G30-H30 -> 1 | J30: =C30*I30 -> 100
A31: 29 | B31: JOSE CUERVO GOLD LTR | C31: 100 | D31: 10 | E31: 5 | H31: 5 | I31: =E31+F31-G31-H31 -> 0 | J31: =C31*I31 -> 0
A32: 30 | B32: JOSE CUERVO SILVER Espec | C32: 100 | D32: 10 | E32: 2 | F32: 3 | H32: 5 | I32: =E32+F32-G32-H32 -> 0 | J32: =C32*I32 -> 0
A33: 31 | B33: TANQUERAY GIN LTR | C33: 200 | D33: 2 | E33: 2 | H33: 2 | I33: =E33+F33-G33-H33 -> 0 | J33: =C33*I33 -> 0
A34: 32 | B34: GORDONS PINK GIN Ltr | C34: 150 | D34: 6 | E34: 2 | H34: 2 | I34: =E34+F34-G34-H34 -> 0 | J34: =C34*I34 -> 0
A35: 33 | B35: GORDONS GIN LTR | C35: 100 | D35: 12 | E35: 2 | F35: 3 | H35: 4 | I35: =E35+F35-G35-H35 -> 1 | J35: =C35*I35 -> 100
A36: 34 | B36: BOMBAY SAPPHIRE GIN LTR | C36: 150 | D36: 12 | E36: 3 | F36: 2 | H36: 4 | I36: =E36+F36-G36-H36 -> 1 | J36: =C36*I36 -> 150
A37: 35 | B37: HENDRICKS GIN 1 LTR | C37: 250 | D37: 10 | E37: 0 | F37: 5 | H37: 4 | I37: =E37+F37-G37-H37 -> 1 | J37: =C37*I37 -> 250
A38: 36 | B38: CAPTAIN MORGAN BLK LTR | C38: 150 | D38: 3 | E38: 4 | H38: 4 | I38: =E38+F38-G38-H38 -> 0 | J38: =C38*I38 -> 0
A39: 37 | B39: CAPTAIN MORGAN SPICED GO | C39: 150 | D39: 3 | E39: 0 | F39: 4 | H39: 2 | I39: =E39+F39-G39-H39 -> 2 | J39: =C39*I39 -> 300
A40: 38 | B40: MALIBU WHITHE RUM LTR | C40: 150 | D40: 5 | E40: 2 | H40: 2 | I40: =E40+F40-G40-H40 -> 0 | J40: =C40*I40 -> 0
...

Sheet ЗАЯВКА
D2: J | E2: B | F2: S | I2: J | J2: B | K2: S
D3: B1 | E3: B2 | F3: B3 | I3: B1 | J3: B2 | K3: B3
B4: 1 | C4: ABSOLUT BLUE LTR | D4: =' JVC'!K3 -> #REF! | E4: =Tikom!K3 | F4: =Selicon!K3 | G4: 62 | H4: HENNESSY XO LTR | I4: =' JVC'!K64 -> #REF! | J4: =Tikom!K64 | K4: =Selicon!K64
B5: 2 | C5: J/W RED LABEL 1 LTR | D5: =' JVC'!K4 -> #REF! | E5: =Tikom!K4 | F5: =Selicon!K4 | G5: 63 | H5: REMY MARTIN VSOP LTR | I5: =' JVC'!K65 -> #REF! | J5: =Tikom!K65 | K5: =Selicon!K65
B6: 3 | C6: J/W BLAK LABEL 1 LTR | D6: =' JVC'!K5 -> #REF! | E6: =Tikom!K5 | F6: =Selicon!K5 | G6: 64 | H6: CHIVAS 18 YRS LTR | I6: =' JVC'!K66 -> #REF! | J6: =Tikom!K66 | K6: =Selicon!K66
B7: 4 | C7: JACK DANIELS LTR | D7: =' JVC'!K6 -> #REF! | E7: =Tikom!K6 | F7: =Selicon!K6 | G7: 65 | H7: ROYAL SALUTE 21 YRS LTR | I7: =' JVC'!K67 -> #REF! | J7: =Tikom!K67 | K7: =Selicon!K67
B8: 5 | C8: CHIVAS REGAL 1 LTR | D8: =' JVC'!K7 -> #REF! | E8: =Tikom!K7 | F8: =Selicon!K7 | G8: 66 | H8: PATRON COFFE | I8: =' JVC'!K68 -> #REF! | J8: =Tikom!K68 | K8: =Selicon!K68
B9: 6 | C9: HEINEKEN BEER CANS 33CL | D9: =' JVC'!K8 -> #REF! | E9: =Tikom!K8 | F9: =Selicon!K8 | G9: 67 | H9: PATRON SILVER 75CL TEQUI | I9: =' JVC'!K69 -> #REF! | J9: =Tikom!K69 | K9: =Selicon!K69
B10: 7 | C10: BUDWEISER BEER CAN 33/35 | D10: =' JVC'!K9 -> #REF! | E10: =Tikom!K9 | F10: =Selicon!K9 | G10: 68 | H10: PATRON ANEJO 75CL GOLD T | I10: =' JVC'!K70 -> #REF! | J10: =Tikom!K70 | K10: =Selicon!K70
B11: 8 | C11: CARLSBERG 50CL Can | D11: =' JVC'!K10 -> #REF! | E11: =Tikom!K10 | F11: =Selicon!K10 | G11: 69 | H11: DON JULIO BLANCO 70/75CL | I11: =' JVC'!K71 -> #REF! | J11: =Tikom!K71 | K11: =Selicon!K71
B12: 9 | C12: RED HORSE 50CL Can | D12: =' JVC'!K11 -> #REF! | E12: =Tikom!K11 | F12: =Selicon!K11 | G12: 70 | H12: DON JULIO REPOSADO 70/75 | I12: =' JVC'!K72 -> #REF! | J12: =Tikom!K72 | K12: =Selicon!K72
B13: 10 | C13: AMSTEL LIGHT Slim Can 35 | D13: =' JVC'!K12 -> #REF! | E13: =Tikom!K12 | F13: =Selicon!K12 | G13: 71 | H13: DON JULIO ANEJO 70/75CL | I13: =' JVC'!K73 -> #REF! | J13: =Tikom!K73 | K13: =Selicon!K73
B14: 11 | C14: CORONA BEER BTL 35.5CL | D14: =' JVC'!K13 -> #REF! | E14: =Tikom!K13 | F14: =Selicon!K13 | G14: 72 | H14: DON JULIO 1942 ANEJO 70 | I14: =' JVC'!K74 -> #REF! | J14: =Tikom!K74 | K14: =Selicon!K74
B15: 12 | C15: STELLA 33CL BTLS | D15: =' JVC'!K14 -> #REF! | E15: =Tikom!K14 | F15: =Selicon!K14 | G15: 73 | H15: ASTI MARTINI 75CL | I15: =' JVC'!K75 -> #REF! | J15: =Tikom!K75 | K15: =Selicon!K75
... B64: 61 | C64: HENNESSY V.S.O.P 1 LTR Pr | D64: =' JVC'!K63 -> #REF! | E64: =Tikom!K63 | F64: =Selicon!K63 | G64: 122 | H64: OYSTER BAY SAUVIGNON | I64: =' JVC'!K124 -> #REF! | J64: =Tikom!K124 | K64: =Selicon!K124

Sheet ДОЛГИ
D4: УЧЕТ ЗАДОЛЖЕННОСТЕЙ
D5: Мы вернули долг | F5: =' JVC'!E131+Tikom!E130+Selicon!E131+' JVC'!F131+' JVC'!G131+' JVC'!H131+' JVC'!I131+' JVC'!J131+' JVC'!K131+Tikom!F130+Tikom!G130+Tikom!H130+Tikom!I130+Tikom!J130+Tikom!K130+Selicon!F131+Selicon!G131+Selicon!H131+Selicon!I131+Selicon!J131+Selicon!K131 -> #REF!
D6: Мы должны | F6: =' JVC'!E132+' JVC'!F132+' JVC'!G132+' JVC'!H132+' JVC'!I132+' JVC'!J132+' JVC'!K132+Tikom!E131+Tikom!F131+Tikom!G131+Tikom!H131+Tikom!I131+Tikom!J131+Tikom!K131+Selicon!E132+Selicon!F132+Selicon!G132+Selicon!H132+Selicon!I132+Selicon!J132+Selicon!K132 -> #REF!
D7: Клиент вернул долг | F7: 1400
D8: Клиент взял в долг | F8: =' JVC'!E134+' JVC'!F134+' JVC'!G134+' JVC'!H134+' JVC'!I134+' JVC'!J134+' JVC'!K134+Tikom!E133+Tikom!F133+Tikom!G133+Tikom!H133+Tikom!I133+Tikom!J133+Tikom!K133+Selicon!E134+Selicon!F134+Selicon!G134+Selicon!H134+Selicon!I134+Selicon!J134+Selicon!K134 -> #REF!
D9: ИТОГО мы должны | F9: =F6-F5 -> #REF!
D10: ИТОГО нам должны | F10: =F8-F7 -> #REF!
D11: БАЛАНС (нам должны больше +/- мы должны больше) | F11: =F9-F10 -> #REF!
